Workbook

Sheet Assumptions
B1: US LFP/ESS CELL PLATFORM — LINE-LEVEL FINANCIAL PROJECTION
B2: Project [ ● ] · Revenue → FCFF · 라인 단위 · Strictly Private & Confidential
B3: Blue=input Black=formula ★=가정값 | ASP = 중국산 셀 + 미국 관세(58.4%) 하한 기반 도출 · SKBA 4라인 · SKOT 3라인
B5: GLOBAL TOGGLE
B6: Effective production factor (명판 대비) ★ | C6: 0.8 | D6: ← 토글: 명판×이 값 = 실제 생산
B7: ASP 방식 토글 ★ (1=관세하한 셀 / 2=DC블록 $155) | C7: 2 | D7: ← 1: 셀 ASP(관세하한) / 2: DC블록 시스템 ASP $155
B8: AMPC 45X ($/kWh) — 셀+모듈(DC블록) · 법정 phase-out | C8: '30=75%·'31=50%… | D8: 0 | E8: 45 | F8: 45 | G8: 45 | H8: 33.75 | I8: 22.5 | J8: 11.25 | K8: 0 | L8: 0 | M8: 0
B10: ASP FLOOR — 중국산 LFP 셀 + 미국 관세 = 미국시장 ASP 하한
B11: 논리: 중국산 셀가×(1+관세 스택)이 미국 ASP의 하한 — 미국산은 그 아래로 팔 이유 없음
B12: $/kWh · % | D12: 2026 | E12: 2027 | F12: 2028 | G12: 2029 | H12: 2030 | I12: 2031 | J12: 2032 | K12: 2033 | L12: 2034 | M12: 2035
B13: 중국산 LFP 셀가 ($/kWh) ★ | C13: '25 내수~$40·수출~$50대 | D13: 52 | E13: 50 | F13: 48 | G13: 46 | H13: 45 | I13: 44 | J13: 43 | K13: 43 | L13: 42 | M13: 42
B14: 기본관세 MFN (%) | C14: 전세계 리튬이온 공통 | D14: 0.034 | E14: 0.034 | F14: 0.034 | G14: 0.034 | H14: 0.034 | I14: 0.034 | J14: 0.034 | K14: 0.034 | L14: 0.034 | M14: 0.034
B15: 상호관세 Reciprocal (%) | C15: Sec.122 등 | D15: 0.1 | E15: 0.1 | F15: 0.1 | G15: 0.1 | H15: 0.1 | I15: 0.1 | J15: 0.1 | K15: 0.1 | L15: 0.1 | M15: 0.1
B16: 펜타닐 IEEPA (%) | D16: 0.2 | E16: 0.2 | F16: 0.2 | G16: 0.2 | H16: 0.2 | I16: 0.2 | J16: 0.2 | K16: 0.2 | L16: 0.2 | M16: 0.2
B17: Section 301 (%) | C17: '26~ 25% (비EV 배터리) | D17: 0.25 | E17: 0.25 | F17: 0.25 | G17: 0.25 | H17: 0.25 | I17: 0.25 | J17: 0.25 | K17: 0.25 | L17: 0.25 | M17: 0.25
B18: 관세 합계 (%) | C18: 합산 | D18: =D14+D15+D16+D17 | E18: =E14+E15+E16+E17 | F18: =F14+F15+F16+F17 | G18: =G14+G15+G16+G17 | H18: =H14+H15+H16+H17 | I18: =I14+I15+I16+I17 | J18: =J14+J15+J16+J17 | K18: =K14+K15+K16+K17 | ... M18: =M14+M15+M16+M17
B19: 관세적용 중국산 = ASP 하한 ($/kWh) | C19: 중국셀가×(1+관세) | D19: =D13*(1+D18) | E19: =E13*(1+E18) | F19: =F13*(1+F18) | G19: =G13*(1+G18) | H19: =H13*(1+H18) | I19: =I13*(1+I18) | J19: =J13*(1+J18) | K19: =K13*(1+K18) | ... M19: =M13*(1+M18)
B20: 미국산 프리미엄 (하한 대비 %) ★ | C20: 통념상 +20% (FEOC·국산 프리미엄) | D20: 0.2 | E20: 0.2 | F20: 0.2 | G20: 0.2 | H20: 0.2 | I20: 0.2 | J20: 0.2 | K20: 0.2 | L20: 0.2 | M20: 0.2
B21: [방식1] 셀 ASP = 하한×(1+프리미엄) | C21: 토글=1일 때 | D21: =D19*(1+D20) | E21: =E19*(1+E20) | F21: =F19*(1+F20) | G21: =G19*(1+G20) | H21: =H19*(1+H20) | I21: =I19*(1+I20) | J21: =J19*(1+J20) | K21: =K19*(1+K20) | ... M21: =M19*(1+M20)
B22: [방식2] DC블록 ASP ($/kWh) ★ | C22: $155 — 셀+모듈+컨테이너 DC블록 통합 | D22: 0 | E22: 155 | F22: 155 | G22: 153 | H22: 151 | I22: 149 | J22: 147 | K22: 145 | L22: 143 | M22: 141
B23: [방식2] 시스템 마진 프리미엄 (%p) ★ | C23: DC블록 GM은 동별 gross margin에 직접 반영 | D23: 0 | E23: 0 | F23: 0 | G23: 0 | H23: 0 | I23: 0 | J23: 0 | K23: 0 | L23: 0 | M23: 0
B24: 적용 마진 프리미엄 (토글 반영) | D24: =IF($C$7=2,D23,0) | E24: =IF($C$7=2,E23,0) | F24: =IF($C$7=2,F23,0) | G24: =IF($C$7=2,G23,0) | H24: =IF($C$7=2,H23,0) | I24: =IF($C$7=2,I23,0) | J24: =IF($C$7=2,J23,0) | K24: =IF($C$7=2,K23,0) | ... M24: =IF($C$7=2,M23,0)
B25: 도출 ASP — 파우치 ($/kWh) | C25: 토글로 선택 | D25: =IF($C$7=2,D22,D21) | E25: =IF($C$7=2,E22,E21) | F25: =IF($C$7=2,F22,F21) | G25: =IF($C$7=2,G22,G21) | H25: =IF($C$7=2,H22,H21) | I25: =IF($C$7=2,I22,I21) | J25: =IF($C$7=2,J22,J21) | K25: =IF($C$7=2,K22,K21) | ... M25: =IF($C$7=2,M22,M21)
B27: 1 · SKBA (공장1) — LFP 파우치 · 1-1동(5.3×2, 자체전극) + 1-2동(전극 외부구매)
B28: per-line | D28: 2026 | E28: 2027 | F28: 2028 | G28: 2029 | H28: 2030 | I28: 2031 | J28: 2032 | K28: 2033 | L28: 2034 | M28: 2035
B29: ▸ 공장1-1동 (파우치, '27, 라인당 5.3GW · 자체 전극)
B30: L1-1A | C30: 파우치 · COD 2027 | D30: 0 | E30: 5.3 | F30: 5.3 | G30: 5.3 | H30: 5.3 | I30: 5.3 | J30: 5.3 | K30: 5.3 | L30: 5.3 | M30: 5.3
B31: └ 가동률 ★ | D31: 0 | E31: 0.55 | F31: 0.7 | G31: 0.8 | H31: 0.88 | I31: 0.9 | J31: 0.9 | K31: 0.9 | L31: 0.9 | M31: 0.9
B32: └ Shipped (GWh) | C32: 명판×가동×토글 | D32: =D30*D31*$C$6 | E32: =E30*E31*$C$6 | F32: =F30*F31*$C$6 | G32: =G30*G31*$C$6 | H32: =H30*H31*$C$6 | I32: =I30*I31*$C$6 | J32: =J30*J31*$C$6 | K32: =K30*K31*$C$6 | ... M32: =M30*M31*$C$6
B33: L1-1B | C33: 파우치 · COD 2027 | D33: 0 | E33: 5.3 | F33: 5.3 | G33: 5.3 | H33: 5.3 | I33: 5.3 | J33: 5.3 | K33: 5.3 | L33: 5.3 | M33: 5.3
B34: └ 가동률 ★ | D34: 0 | E34: 0.55 | F34: 0.7 | G34: 0.8 | H34: 0.88 | I34: 0.9 | J34: 0.9 | K34: 0.9 | L34: 0.9 | M34: 0.9
B35: └ Shipped (GWh) | C35: 명판×가동×토글 | D35: =D33*D34*$C$6 | E35: =E33*E34*$C$6 | F35: =F33*F34*$C$6 | G35: =G33*G34*$C$6 | H35: =H33*H34*$C$6 | I35: =I33*I34*$C$6 | J35: =J33*J34*$C$6 | K35: =K33*K34*$C$6 | ... M35: =M33*M34*$C$6
B36: ▸ 공장1-2동 (파우치, '28, 전극 외부구매)
B37: L1-2C | C37: 파우치 · COD 2028 | D37: 0 | E37: 0 | F37: 5.3 | G37: 5.3 | H37: 5.3 | I37: 5.3 | J37: 5.3 | K37: 5.3 | L37: 5.3 | M37: 5.3
B38: └ 가동률 ★ | D38: 0 | E38: 0 | F38: 0.55 | G38: 0.7 | H38: 0.82 | I38: 0.88 | J38: 0.9 | K38: 0.9 | L38: 0.9 | M38: 0.9
B39: └ Shipped (GWh) | C39: 명판×가동×토글 | D39: =D37*D38*$C$6 | E39: =E37*E38*$C$6 | F39: =F37*F38*$C$6 | G39: =G37*G38*$C$6 | H39: =H37*H38*$C$6 | I39: =I37*I38*$C$6 | J39: =J37*J38*$C$6 | K39: =K37*K38*$C$6 | ... M39: =M37*M38*$C$6
B40: L1-2D | C40: 파우치 · COD 2028 | D40: 0 | E40: 0 | F40: 5.3 | G40: 5.3 | H40: 5.3 | I40: 5.3 | J40: 5.3 | K40: 5.3 | L40: 5.3 | M40: 5.3
B41: └ 가동률 ★ | D41: 0 | E41: 0 | F41: 0.55 | G41: 0.7 | H41: 0.82 | I41: 0.88 | J41: 0.9 | K41: 0.9 | L41: 0.9 | M41: 0.9
B42: └ Shipped (GWh) | C42: 명판×가동×토글 | D42: =D40*D41*$C$6 | E42: =E40*E41*$C$6 | F42: =F40*F41*$C$6 | G42: =G40*G41*$C$6 | H42: =H40*H41*$C$6 | I42: =I40*I41*$C$6 | J42: =J40*J41*$C$6 | K42: =K40*K41*$C$6 | ... M42: =M40*M41*$C$6
B43: 1-1동 shipped (GWh) | C43: 자체 전극 | D43: =D32+D35 | E43: =E32+E35 | F43: =F32+F35 | G43: =G32+G35 | H43: =H32+H35 | I43: =I32+I35 | J43: =J32+J35 | K43: =K32+K35 | ... M43: =M32+M35
...

Sheet SKBA
B1: SKBA — P&L → FCFF (4개 파우치 라인)
B2: 공장1-1(L1-1A/B '27) + 공장1-2(L1-2C/D '28) · 라인 합산
B4: REVENUE
B5: ($mm) | D5: 2026 | E5: 2027 | F5: 2028 | G5: 2029 | H5: 2030 | I5: 2031 | J5: 2032 | K5: 2033 | L5: 2034 | M5: 2035
B6: Shipped (GWh) | D6: =Assumptions!D45 | E6: =Assumptions!E45 | F6: =Assumptions!F45 | G6: =Assumptions!G45 | H6: =Assumptions!H45 | I6: =Assumptions!I45 | J6: =Assumptions!J45 | K6: =Assumptions!K45 | ... M6: =Assumptions!M45
B7: ASP ($/kWh) | D7: =Assumptions!D46 | E7: =Assumptions!E46 | F7: =Assumptions!F46 | G7: =Assumptions!G46 | H7: =Assumptions!H46 | I7: =Assumptions!I46 | J7: =Assumptions!J46 | K7: =Assumptions!K46 | ... M7: =Assumptions!M46
B8: Revenue | D8: =D6*D7 | E8: =E6*E7 | F8: =F6*F7 | G8: =G6*G7 | H8: =H6*H7 | I8: =I6*I7 | J8: =J6*J7 | K8: =K6*K7 | ... M8: =M6*M7
B9: Cash COGS (1-1동+1-2동) | D9: =-(Assumptions!D43*Assumptions!D49+Assumptions!D44*Assumptions!D50) | E9: =-(Assumptions!E43*Assumptions!E49+Assumptions!E44*Assumptions!E50) | F9: =-(Assumptions!F43*Assumptions!F49+Assumptions!F44*Assumptions!F50) | G9: =-(Assumptions!G43*Assumptions!G49+Assumptions!G44*Assumptions!G50) | H9: =-(Assumptions!H43*Assumptions!H49+Assumptions!H44*Assumptions!H50) | I9: =-(Assumptions!I43*Assumptions!I49+Assumptions!I44*Assumptions!I50) | J9: =-(Assumptions!J43*Assumptions!J49+Assumptions!J44*Assumptions!J50) | K9: =-(Assumptions!K43*Assumptions!K49+Assumptions!K44*Assumptions!K50) | ... M9: =-(Assumptions!M43*Assumptions!M49+Assumptions!M44*Assumptions!M50)
B10: COST & EBIT
B11: ($mm) | D11: 2026 | E11: 2027 | F11: 2028 | G11: 2029 | H11: 2030 | I11: 2031 | J11: 2032 | K11: 2033 | L11: 2034 | M11: 2035
B12: Gross profit (pre-AMPC) | D12: =D8+D9 | E12: =E8+E9 | F12: =F8+F9 | G12: =G8+G9 | H12: =H8+H9 | I12: =I8+I9 | J12: =J8+J9 | K12: =K8+K9 | ... M12: =M8+M9
B13: SG&A | D13: =-D8*Assumptions!$C$81 | E13: =-E8*Assumptions!$C$81 | F13: =-F8*Assumptions!$C$81 | G13: =-G8*Assumptions!$C$81 | H13: =-H8*Assumptions!$C$81 | I13: =-I8*Assumptions!$C$81 | J13: =-J8*Assumptions!$C$81 | K13: =-K8*Assumptions!$C$81 | ... M13: =-M8*Assumptions!$C$81
B14: Gross PP&E (cum.) | D14: =Assumptions!D53 | E14: =D14+Assumptions!E53 | F14: =E14+Assumptions!F53 | G14: =F14+Assumptions!G53 | H14: =G14+Assumptions!H53 | I14: =H14+Assumptions!I53 | J14: =I14+Assumptions!J53 | K14: =J14+Assumptions!K53 | L14: =K14+Assumptions!L53 | M14: =L14+Assumptions!M53
B15: D&A | D15: =-D14*Assumptions!$C$82 | E15: =-E14*Assumptions!$C$82 | F15: =-F14*Assumptions!$C$82 | G15: =-G14*Assumptions!$C$82 | H15: =-H14*Assumptions!$C$82 | I15: =-I14*Assumptions!$C$82 | J15: =-J14*Assumptions!$C$82 | K15: =-K14*Assumptions!$C$82 | ... M15: =-M14*Assumptions!$C$82
B16: EBIT (pre-AMPC) | D16: =D12+D13+D15 | E16: =E12+E13+E15 | F16: =F12+F13+F15 | G16: =G12+G13+G15 | H16: =H12+H13+H15 | I16: =I12+I13+I15 | J16: =J12+J13+J15 | K16: =K12+K13+K15 | ... M16: =M12+M13+M15
B17: margin pre-AMPC | D17: =IF(D8=0,0,D16/D8) | E17: =IF(E8=0,0,E16/E8) | F17: =IF(F8=0,0,F16/F8) | G17: =IF(G8=0,0,G16/G8) | H17: =IF(H8=0,0,H16/H8) | I17: =IF(I8=0,0,I16/I8) | J17: =IF(J8=0,0,J16/J8) | K17: =IF(K8=0,0,K16/K8) | ... M17: =IF(M8=0,0,M16/M8)
B18: Plus: AMPC 45X | D18: =(Assumptions!D45)*Assumptions!D8 | E18: =(Assumptions!E45)*Assumptions!E8 | F18: =(Assumptions!F45)*Assumptions!F8 | G18: =(Assumptions!G45)*Assumptions!G8 | H18: =(Assumptions!H45)*Assumptions!H8 | I18: =(Assumptions!I45)*Assumptions!I8 | J18: =(Assumptions!J45)*Assumptions!J8 | K18: =(Assumptions!K45)*Assumptions!K8 | ... M18: =(Assumptions!M45)*Assumptions!M8
B19: EBIT (incl. AMPC) | D19: =D16+D18 | E19: =E16+E18 | F19: =F16+F18 | G19: =G16+G18 | H19: =H16+H18 | I19: =I16+I18 | J19: =J16+J18 | K19: =K16+K18 | ... M19: =M16+M18
B21: UNLEVERED FCFF
B22: ($mm) | D22: 2026 | E22: 2027 | F22: 2028 | G22: 2029 | H22: 2030 | I22: 2031 | J22: 2032 | K22: 2033 | L22: 2034 | M22: 2035
B23: 과세소득 pre-NOL | D23: =MAX(0,D16) | E23: =MAX(0,E16) | F23: =MAX(0,F16) | G23: =MAX(0,G16) | H23: =MAX(0,H16) | I23: =MAX(0,I16) | J23: =MAX(0,J16) | K23: =MAX(0,K16) | ... M23: =MAX(0,M16)
B24: NOL 기초잔액 | D24: =Assumptions!$C$87 | E24: =D27 | F24: =E27 | G24: =F27 | H24: =G27 | I24: =H27 | J24: =I27 | K24: =J27 | L24: =K27 | M24: =L27
B25: NOL 사용 (80% 한도) | D25: =MIN(D24,D23*Assumptions!$C$89) | E25: =MIN(E24,E23*Assumptions!$C$89) | F25: =MIN(F24,F23*Assumptions!$C$89) | G25: =MIN(G24,G23*Assumptions!$C$89) | H25: =MIN(H24,H23*Assumptions!$C$89) | I25: =MIN(I24,I23*Assumptions!$C$89) | J25: =MIN(J24,J23*Assumptions!$C$89) | K25: =MIN(K24,K23*Assumptions!$C$89) | ... M25: =MIN(M24,M23*Assumptions!$C$89)
B26: NOL 추가 (당기손실) | D26: =MAX(0,-D16) | E26: =MAX(0,-E16) | F26: =MAX(0,-F16) | G26: =MAX(0,-G16) | H26: =MAX(0,-H16) | I26: =MAX(0,-I16) | J26: =MAX(0,-J16) | K26: =MAX(0,-K16) | ... M26: =MAX(0,-M16)
B27: NOL 기말잔액 | D27: =D24-D25+D26 | E27: =E24-E25+E26 | F27: =F24-F25+F26 | G27: =G24-G25+G26 | H27: =H24-H25+H26 | I27: =I24-I25+I26 | J27: =J24-J25+J26 | K27: =K24-K25+K26 | ... M27: =M24-M25+M26
B28: 과세소득 post-NOL | D28: =D23-D25 | E28: =E23-E25 | F28: =F23-F25 | G28: =G23-G25 | H28: =H23-H25 | I28: =I23-I25 | J28: =J23-J25 | K28: =K23-K25 | ... M28: =M23-M25
B29: 현금세금 (AMPC 비과세) | D29: =-D28*Assumptions!$C$86 | E29: =-E28*Assumptions!$C$86 | F29: =-F28*Assumptions!$C$86 | G29: =-G28*Assumptions!$C$86 | H29: =-H28*Assumptions!$C$86 | I29: =-I28*Assumptions!$C$86 | J29: =-J28*Assumptions!$C$86 | K29: =-K28*Assumptions!$C$86 | ... M29: =-M28*Assumptions!$C$86
B30: NOPAT (NOL 반영) | D30: =D19+D29 | E30: =E19+E29 | F30: =F19+F29 | G30: =G19+G29 | H30: =H19+H29 | I30: =I19+I29 | J30: =J19+J29 | K30: =K19+K29 | ... M30: =M19+M29
B31: Plus: D&A | D31: =-D15 | E31: =-E15 | F31: =-F15 | G31: =-G15 | H31: =-H15 | I31: =-I15 | J31: =-J15 | K31: =-K15 | ... M31: =-M15
B32: Less: maint capex | D32: =-D8*Assumptions!$C$83 | E32: =-E8*Assumptions!$C$83 | F32: =-F8*Assumptions!$C$83 | G32: =-G8*Assumptions!$C$83 | H32: =-H8*Assumptions!$C$83 | I32: =-I8*Assumptions!$C$83 | J32: =-J8*Assumptions!$C$83 | K32: =-K8*Assumptions!$C$83 | ... M32: =-M8*Assumptions!$C$83
B33: Less: growth capex | D33: =-Assumptions!D53 | E33: =-Assumptions!E53 | F33: =-Assumptions!F53 | G33: =-Assumptions!G53 | H33: =-Assumptions!H53 | I33: =-Assumptions!I53 | J33: =-Assumptions!J53 | K33: =-Assumptions!K53 | ... M33: =-Assumptions!M53
B34: Plus: CapEx 그랜트 (10%) | D34: =Assumptions!D53*Assumptions!$C$84 | E34: =Assumptions!E53*Assumptions!$C$84 | F34: =Assumptions!F53*Assumptions!$C$84 | G34: =Assumptions!G53*Assumptions!$C$84 | H34: =Assumptions!H53*Assumptions!$C$84 | I34: =Assumptions!I53*Assumptions!$C$84 | J34: =Assumptions!J53*Assumptions!$C$84 | K34: =Assumptions!K53*Assumptions!$C$84 | ... M34: =Assumptions!M53*Assumptions!$C$84
B35: NWC level | D35: =D8*Assumptions!$C$85 | E35: =E8*Assumptions!$C$85 | F35: =F8*Assumptions!$C$85 | G35: =G8*Assumptions!$C$85 | H35: =H8*Assumptions!$C$85 | I35: =I8*Assumptions!$C$85 | J35: =J8*Assumptions!$C$85 | K35: =K8*Assumptions!$C$85 | ... M35: =M8*Assumptions!$C$85
B36: Less: ΔNWC | D36: =-D35 | E36: =-(E35-D35) | F36: =-(F35-E35) | G36: =-(G35-F35) | H36: =-(H35-G35) | I36: =-(I35-H35) | J36: =-(J35-I35) | K36: =-(K35-J35) | L36: =-(L35-K35) | M36: =-(M35-L35)
B37: Unlevered FCFF | D37: =D30+D31+D32+D33+D34+D36 | E37: =E30+E31+E32+E33+E34+E36 | F37: =F30+F31+F32+F33+F34+F36 | G37: =G30+G31+G32+G33+G34+G36 | H37: =H30+H31+H32+H33+H34+H36 | I37: =I30+I31+I32+I33+I34+I36 | J37: =J30+J31+J32+J33+J34+J36 | K37: =K30+K31+K32+K33+K34+K36 | ... M37: =M30+M31+M32+M33+M34+M36

Sheet SKOT
B1: SKOT — P&L → FCFF (각형 2라인 + 파우치 1라인)
B2: 폼팩터별 매출 분리 · 각형 13.5×2 + 파우치 2.7 = 29.7GWh · COD '28
B4: REVENUE — by formfactor
B5: ($mm) | D5: 2026 | E5: 2027 | F5: 2028 | G5: 2029 | H5: 2030 | I5: 2031 | J5: 2032 | K5: 2033 | L5: 2034 | M5: 2035
B6: 각형 revenue | D6: =Assumptions!D69*Assumptions!D72 | E6: =Assumptions!E69*Assumptions!E72 | F6: =Assumptions!F69*Assumptions!F72 | G6: =Assumptions!G69*Assumptions!G72 | H6: =Assumptions!H69*Assumptions!H72 | I6: =Assumptions!I69*Assumptions!I72 | J6: =Assumptions!J69*Assumptions!J72 | K6: =Assumptions!K69*Assumptions!K72 | ... M6: =Assumptions!M69*Assumptions!M72
B7: 파우치 revenue | D7: =Assumptions!D70*Assumptions!D75 | E7: =Assumptions!E70*Assumptions!E75 | F7: =Assumptions!F70*Assumptions!F75 | G7: =Assumptions!G70*Assumptions!G75 | H7: =Assumptions!H70*Assumptions!H75 | I7: =Assumptions!I70*Assumptions!I75 | J7: =Assumptions!J70*Assumptions!J75 | K7: =Assumptions!K70*Assumptions!K75 | ... M7: =Assumptions!M70*Assumptions!M75
B8: Revenue (total) | D8: =D6+D7 | E8: =E6+E7 | F8: =F6+F7 | G8: =G6+G7 | H8: =H6+H7 | I8: =I6+I7 | J8: =J6+J7 | K8: =K6+K7 | ... M8: =M6+M7
B9: Cash COGS (by formfactor) | D9: =-(Assumptions!D69*Assumptions!D74+Assumptions!D70*Assumptions!D77) | E9: =-(Assumptions!E69*Assumptions!E74+Assumptions!E70*Assumptions!E77) | F9: =-(Assumptions!F69*Assumptions!F74+Assumptions!F70*Assumptions!F77) | G9: =-(Assumptions!G69*Assumptions!G74+Assumptions!G70*Assumptions!G77) | H9: =-(Assumptions!H69*Assumptions!H74+Assumptions!H70*Assumptions!H77) | I9: =-(Assumptions!I69*Assumptions!I74+Assumptions!I70*Assumptions!I77) | J9: =-(Assumptions!J69*Assumptions!J74+Assumptions!J70*Assumptions!J77) | K9: =-(Assumptions!K69*Assumptions!K74+Assumptions!K70*Assumptions!K77) | ... M9: =-(Assumptions!M69*Assumptions!M74+Assumptions!M70*Assumptions!M77)
B10: COST & EBIT
B11: ($mm) | D11: 2026 | E11: 2027 | F11: 2028 | G11: 2029 | H11: 2030 | I11: 2031 | J11: 2032 | K11: 2033 | L11: 2034 | M11: 2035
B12: Gross profit (pre-AMPC) | D12: =D8+D9 | E12: =E8+E9 | F12: =F8+F9 | G12: =G8+G9 | H12: =H8+H9 | I12: =I8+I9 | J12: =J8+J9 | K12: =K8+K9 | ... M12: =M8+M9
B13: SG&A | D13: =-D8*Assumptions!$C$81 | E13: =-E8*Assumptions!$C$81 | F13: =-F8*Assumptions!$C$81 | G13: =-G8*Assumptions!$C$81 | H13: =-H8*Assumptions!$C$81 | I13: =-I8*Assumptions!$C$81 | J13: =-J8*Assumptions!$C$81 | K13: =-K8*Assumptions!$C$81 | ... M13: =-M8*Assumptions!$C$81
B14: Gross PP&E (cum.) | D14: =Assumptions!D78 | E14: =D14+Assumptions!E78 | F14: =E14+Assumptions!F78 | G14: =F14+Assumptions!G78 | H14: =G14+Assumptions!H78 | I14: =H14+Assumptions!I78 | J14: =I14+Assumptions!J78 | K14: =J14+Assumptions!K78 | L14: =K14+Assumptions!L78 | M14: =L14+Assumptions!M78
B15: D&A | D15: =-D14*Assumptions!$C$82 | E15: =-E14*Assumptions!$C$82 | F15: =-F14*Assumptions!$C$82 | G15: =-G14*Assumptions!$C$82 | H15: =-H14*Assumptions!$C$82 | I15: =-I14*Assumptions!$C$82 | J15: =-J14*Assumptions!$C$82 | K15: =-K14*Assumptions!$C$82 | ... M15: =-M14*Assumptions!$C$82
B16: EBIT (pre-AMPC) | D16: =D12+D13+D15 | E16: =E12+E13+E15 | F16: =F12+F13+F15 | G16: =G12+G13+G15 | H16: =H12+H13+H15 | I16: =I12+I13+I15 | J16: =J12+J13+J15 | K16: =K12+K13+K15 | ... M16: =M12+M13+M15
B17: margin pre-AMPC | D17: =IF(D8=0,0,D16/D8) | E17: =IF(E8=0,0,E16/E8) | F17: =IF(F8=0,0,F16/F8) | G17: =IF(G8=0,0,G16/G8) | H17: =IF(H8=0,0,H16/H8) | I17: =IF(I8=0,0,I16/I8) | J17: =IF(J8=0,0,J16/J8) | K17: =IF(K8=0,0,K16/K8) | ... M17: =IF(M8=0,0,M16/M8)
B18: Plus: AMPC 45X | D18: =(Assumptions!D69+Assumptions!D70)*Assumptions!D8 | E18: =(Assumptions!E69+Assumptions!E70)*Assumptions!E8 | F18: =(Assumptions!F69+Assumptions!F70)*Assumptions!F8 | G18: =(Assumptions!G69+Assumptions!G70)*Assumptions!G8 | H18: =(Assumptions!H69+Assumptions!H70)*Assumptions!H8 | I18: =(Assumptions!I69+Assumptions!I70)*Assumptions!I8 | J18: =(Assumptions!J69+Assumptions!J70)*Assumptions!J8 | K18: =(Assumptions!K69+Assumptions!K70)*Assumptions!K8 | ... M18: =(Assumptions!M69+Assumptions!M70)*Assumptions!M8
B19: EBIT (incl. AMPC) | D19: =D16+D18 | E19: =E16+E18 | F19: =F16+F18 | G19: =G16+G18 | H19: =H16+H18 | I19: =I16+I18 | J19: =J16+J18 | K19: =K16+K18 | ... M19: =M16+M18
B21: UNLEVERED FCFF
B22: ($mm) | D22: 2026 | E22: 2027 | F22: 2028 | G22: 2029 | H22: 2030 | I22: 2031 | J22: 2032 | K22: 2033 | L22: 2034 | M22: 2035
B23: 과세소득 pre-NOL | D23: =MAX(0,D16) | E23: =MAX(0,E16) | F23: =MAX(0,F16) | G23: =MAX(0,G16) | H23: =MAX(0,H16) | I23: =MAX(0,I16) | J23: =MAX(0,J16) | K23: =MAX(0,K16) | ... M23: =MAX(0,M16)
B24: NOL 기초잔액 | D24: =Assumptions!$C$88 | E24: =D27 | F24: =E27 | G24: =F27 | H24: =G27 | I24: =H27 | J24: =I27 | K24: =J27 | L24: =K27 | M24: =L27
B25: NOL 사용 (80% 한도) | D25: =MIN(D24,D23*Assumptions!$C$89) | E25: =MIN(E24,E23*Assumptions!$C$89) | F25: =MIN(F24,F23*Assumptions!$C$89) | G25: =MIN(G24,G23*Assumptions!$C$89) | H25: =MIN(H24,H23*Assumptions!$C$89) | I25: =MIN(I24,I23*Assumptions!$C$89) | J25: =MIN(J24,J23*Assumptions!$C$89) | K25: =MIN(K24,K23*Assumptions!$C$89) | ... M25: =MIN(M24,M23*Assumptions!$C$89)
B26: NOL 추가 (당기손실) | D26: =MAX(0,-D16) | E26: =MAX(0,-E16) | F26: =MAX(0,-F16) | G26: =MAX(0,-G16) | H26: =MAX(0,-H16) | I26: =MAX(0,-I16) | J26: =MAX(0,-J16) | K26: =MAX(0,-K16) | ... M26: =MAX(0,-M16)
B27: NOL 기말잔액 | D27: =D24-D25+D26 | E27: =E24-E25+E26 | F27: =F24-F25+F26 | G27: =G24-G25+G26 | H27: =H24-H25+H26 | I27: =I24-I25+I26 | J27: =J24-J25+J26 | K27: =K24-K25+K26 | ... M27: =M24-M25+M26
B28: 과세소득 post-NOL | D28: =D23-D25 | E28: =E23-E25 | F28: =F23-F25 | G28: =G23-G25 | H28: =H23-H25 | I28: =I23-I25 | J28: =J23-J25 | K28: =K23-K25 | ... M28: =M23-M25
B29: 현금세금 (AMPC 비과세) | D29: =-D28*Assumptions!$C$86 | E29: =-E28*Assumptions!$C$86 | F29: =-F28*Assumptions!$C$86 | G29: =-G28*Assumptions!$C$86 | H29: =-H28*Assumptions!$C$86 | I29: =-I28*Assumptions!$C$86 | J29: =-J28*Assumptions!$C$86 | K29: =-K28*Assumptions!$C$86 | ... M29: =-M28*Assumptions!$C$86
B30: NOPAT (NOL 반영) | D30: =D19+D29 | E30: =E19+E29 | F30: =F19+F29 | G30: =G19+G29 | H30: =H19+H29 | I30: =I19+I29 | J30: =J19+J29 | K30: =K19+K29 | ... M30: =M19+M29
B31: Plus: D&A | D31: =-D15 | E31: =-E15 | F31: =-F15 | G31: =-G15 | H31: =-H15 | I31: =-I15 | J31: =-J15 | K31: =-K15 | ... M31: =-M15
B32: Less: maint capex | D32: =-D8*Assumptions!$C$83 | E32: =-E8*Assumptions!$C$83 | F32: =-F8*Assumptions!$C$83 | G32: =-G8*Assumptions!$C$83 | H32: =-H8*Assumptions!$C$83 | I32: =-I8*Assumptions!$C$83 | J32: =-J8*Assumptions!$C$83 | K32: =-K8*Assumptions!$C$83 | ... M32: =-M8*Assumptions!$C$83
B33: Less: growth capex | D33: =-Assumptions!D78 | E33: =-Assumptions!E78 | F33: =-Assumptions!F78 | G33: =-Assumptions!G78 | H33: =-Assumptions!H78 | I33: =-Assumptions!I78 | J33: =-Assumptions!J78 | K33: =-Assumptions!K78 | ... M33: =-Assumptions!M78
B34: Plus: CapEx 그랜트 (10%) | D34: =Assumptions!D78*Assumptions!$C$84 | E34: =Assumptions!E78*Assumptions!$C$84 | F34: =Assumptions!F78*Assumptions!$C$84 | G34: =Assumptions!G78*Assumptions!$C$84 | H34: =Assumptions!H78*Assumptions!$C$84 | I34: =Assumptions!I78*Assumptions!$C$84 | J34: =Assumptions!J78*Assumptions!$C$84 | K34: =Assumptions!K78*Assumptions!$C$84 | ... M34: =Assumptions!M78*Assumptions!$C$84
B35: NWC level | D35: =D8*Assumptions!$C$85 | E35: =E8*Assumptions!$C$85 | F35: =F8*Assumptions!$C$85 | G35: =G8*Assumptions!$C$85 | H35: =H8*Assumptions!$C$85 | I35: =I8*Assumptions!$C$85 | J35: =J8*Assumptions!$C$85 | K35: =K8*Assumptions!$C$85 | ... M35: =M8*Assumptions!$C$85
B36: Less: ΔNWC | D36: =-D35 | E36: =-(E35-D35) | F36: =-(F35-E35) | G36: =-(G35-F35) | H36: =-(H35-G35) | I36: =-(I35-H35) | J36: =-(J35-I35) | K36: =-(K35-J35) | L36: =-(L35-K35) | M36: =-(M35-L35)
B37: Unlevered FCFF | D37: =D30+D31+D32+D33+D34+D36 | E37: =E30+E31+E32+E33+E34+E36 | F37: =F30+F31+F32+F33+F34+F36 | G37: =G30+G31+G32+G33+G34+G36 | H37: =H30+H31+H32+H33+H34+H36 | I37: =I30+I31+I32+I33+I34+I36 | J37: =J30+J31+J32+J33+J34+J36 | K37: =K30+K31+K32+K33+K34+K36 | ... M37: =M30+M31+M32+M33+M34+M36

Sheet Consolidated
B1: CONSOLIDATED — SKBA + SKOT → FCFF → DCF
B2: 라인 단위 합산 · $mm · FCFF unlevered · AMPC 옵션A · SKOT placeholder 입력 시 합산
B4: REVENUE — by plant
B5: ($mm) | D5: 2026 | E5: 2027 | F5: 2028 | G5: 2029 | H5: 2030 | I5: 2031 | J5: 2032 | K5: 2033 | L5: 2034 | M5: 2035
B6: SKBA revenue (파우치) | D6: =SKBA!D8 | E6: =SKBA!E8 | F6: =SKBA!F8 | G6: =SKBA!G8 | H6: =SKBA!H8 | I6: =SKBA!I8 | J6: =SKBA!J8 | K6: =SKBA!K8 | ... M6: =SKBA!M8
B7: SKOT revenue (각형+파우치) | D7: =SKOT!D8 | E7: =SKOT!E8 | F7: =SKOT!F8 | G7: =SKOT!G8 | H7: =SKOT!H8 | I7: =SKOT!I8 | J7: =SKOT!J8 | K7: =SKOT!K8 | ... M7: =SKOT!M8
B8: Total revenue | D8: =D6+D7 | E8: =E6+E7 | F8: =F6+F7 | G8: =G6+G7 | H8: =H6+H7 | I8: =I6+I7 | J8: =J6+J7 | K8: =K6+K7 | ... M8: =M6+M7
B9: Total shipped (GWh) | D9: =SKBA!D6+Assumptions!D69+Assumptions!D70 | E9: =SKBA!E6+Assumptions!E69+Assumptions!E70 | F9: =SKBA!F6+Assumptions!F69+Assumptions!F70 | G9: =SKBA!G6+Assumptions!G69+Assumptions!G70 | H9: =SKBA!H6+Assumptions!H69+Assumptions!H70 | I9: =SKBA!I6+Assumptions!I69+Assumptions!I70 | J9: =SKBA!J6+Assumptions!J69+Assumptions!J70 | K9: =SKBA!K6+Assumptions!K69+Assumptions!K70 | ... M9: =SKBA!M6+Assumptions!M69+Assumptions!M70
B11: EBIT
B12: ($mm) | D12: 2026 | E12: 2027 | F12: 2028 | G12: 2029 | H12: 2030 | I12: 2031 | J12: 2032 | K12: 2033 | L12: 2034 | M12: 2035
B13: EBIT pre-AMPC | D13: =SKBA!D16+SKOT!D16 | E13: =SKBA!E16+SKOT!E16 | F13: =SKBA!F16+SKOT!F16 | G13: =SKBA!G16+SKOT!G16 | H13: =SKBA!H16+SKOT!H16 | I13: =SKBA!I16+SKOT!I16 | J13: =SKBA!J16+SKOT!J16 | K13: =SKBA!K16+SKOT!K16 | ... M13: =SKBA!M16+SKOT!M16
B14: margin pre-AMPC | D14: =IF(D8=0,0,D13/D8) | E14: =IF(E8=0,0,E13/E8) | F14: =IF(F8=0,0,F13/F8) | G14: =IF(G8=0,0,G13/G8) | H14: =IF(H8=0,0,H13/H8) | I14: =IF(I8=0,0,I13/I8) | J14: =IF(J8=0,0,J13/J8) | K14: =IF(K8=0,0,K13/K8) | ... M14: =IF(M8=0,0,M13/M8)
B15: Plus: AMPC 45X | D15: =SKBA!D18+SKOT!D18 | E15: =SKBA!E18+SKOT!E18 | F15: =SKBA!F18+SKOT!F18 | G15: =SKBA!G18+SKOT!G18 | H15: =SKBA!H18+SKOT!H18 | I15: =SKBA!I18+SKOT!I18 | J15: =SKBA!J18+SKOT!J18 | K15: =SKBA!K18+SKOT!K18 | ... M15: =SKBA!M18+SKOT!M18
B16: EBIT incl. AMPC | D16: =SKBA!D19+SKOT!D19 | E16: =SKBA!E19+SKOT!E19 | F16: =SKBA!F19+SKOT!F19 | G16: =SKBA!G19+SKOT!G19 | H16: =SKBA!H19+SKOT!H19 | I16: =SKBA!I19+SKOT!I19 | J16: =SKBA!J19+SKOT!J19 | K16: =SKBA!K19+SKOT!K19 | ... M16: =SKBA!M19+SKOT!M19
B17: margin incl. AMPC | D17: =IF(D8=0,0,D16/D8) | E17: =IF(E8=0,0,E16/E8) | F17: =IF(F8=0,0,F16/F8) | G17: =IF(G8=0,0,G16/G8) | H17: =IF(H8=0,0,H16/H8) | I17: =IF(I8=0,0,I16/I8) | J17: =IF(J8=0,0,J16/J8) | K17: =IF(K8=0,0,K16/K8) | ... M17: =IF(M8=0,0,M16/M8)
B18: Plus: D&A | D18: =-(SKBA!D15+SKOT!D15) | E18: =-(SKBA!E15+SKOT!E15) | F18: =-(SKBA!F15+SKOT!F15) | G18: =-(SKBA!G15+SKOT!G15) | H18: =-(SKBA!H15+SKOT!H15) | I18: =-(SKBA!I15+SKOT!I15) | J18: =-(SKBA!J15+SKOT!J15) | K18: =-(SKBA!K15+SKOT!K15) | ... M18: =-(SKBA!M15+SKOT!M15)
B19: EBITDA incl. AMPC | D19: =D16+D18 | E19: =E16+E18 | F19: =F16+F18 | G19: =G16+G18 | H19: =H16+H18 | I19: =I16+I18 | J19: =J16+J18 | K19: =K16+K18 | ... M19: =M16+M18
B20: EBITDA margin | D20: =IF(D8=0,0,D19/D8) | E20: =IF(E8=0,0,E19/E8) | F20: =IF(F8=0,0,F19/F8) | G20: =IF(G8=0,0,G19/G8) | H20: =IF(H8=0,0,H19/H8) | I20: =IF(I8=0,0,I19/I8) | J20: =IF(J8=0,0,J19/J8) | K20: =IF(K8=0,0,K19/K8) | ... M20: =IF(M8=0,0,M19/M8)
B21: EBITDA ex-AMPC (멀티플용) | D21: =D19-D15 | E21: =E19-E15 | F21: =F19-F15 | G21: =G19-G15 | H21: =H19-H15 | I21: =I19-I15 | J21: =J19-J15 | K21: =K19-K15 | ... M21: =M19-M15
B22: EBITDA ex-AMPC margin | D22: =IF(D8=0,0,D21/D8) | E22: =IF(E8=0,0,E21/E8) | F22: =IF(F8=0,0,F21/F8) | G22: =IF(G8=0,0,G21/G8) | H22: =IF(H8=0,0,H21/H8) | I22: =IF(I8=0,0,I21/I8) | J22: =IF(J8=0,0,J21/J8) | K22: =IF(K8=0,0,K21/K8) | ... M22: =IF(M8=0,0,M21/M8)
B24: UNLEVERED FCFF
B25: ($mm) | D25: 2026 | E25: 2027 | F25: 2028 | G25: 2029 | H25: 2030 | I25: 2031 | J25: 2032 | K25: 2033 | L25: 2034 | M25: 2035
B26: SKBA FCFF | D26: =SKBA!D37 | E26: =SKBA!E37 | F26: =SKBA!F37 | G26: =SKBA!G37 | H26: =SKBA!H37 | I26: =SKBA!I37 | J26: =SKBA!J37 | K26: =SKBA!K37 | ... M26: =SKBA!M37
B27: SKOT FCFF | D27: =SKOT!D37 | E27: =SKOT!E37 | F27: =SKOT!F37 | G27: =SKOT!G37 | H27: =SKOT!H37 | I27: =SKOT!I37 | J27: =SKOT!J37 | K27: =SKOT!K37 | ... M27: =SKOT!M37
B28: Consolidated FCFF | D28: =D26+D27 | E28: =E26+E27 | F28: =F26+F27 | G28: =G26+G27 | H28: =H26+H27 | I28: =I26+I27 | J28: =J26+J27 | K28: =K26+K27 | ... M28: =M26+M27
B30: FCFE — 공장별 (하이브리드: HoldCo 우산 + ring-fence)
B31: ($mm) | D31: 2026 | E31: 2027 | F31: 2028 | G31: 2029 | H31: 2030 | I31: 2031 | J31: 2032 | K31: 2033 | L31: 2034 | M31: 2035
B32: SKBA · 이자비용 (project debt) | D32: =-Assumptions!$C$102*Assumptions!$C$103 | E32: =-Assumptions!$C$102*Assumptions!$C$103 | F32: =-Assumptions!$C$102*Assumptions!$C$103 | G32: =-Assumptions!$C$102*Assumptions!$C$103 | H32: =-Assumptions!$C$102*Assumptions!$C$103 | I32: =-Assumptions!$C$102*Assumptions!$C$103 | J32: =-Assumptions!$C$102*Assumptions!$C$103 | K32: =-Assumptions!$C$102*Assumptions!$C$103 | ... M32: =-Assumptions!$C$102*Assumptions!$C$103
B33: SKBA · 이자 tax shield | D33: =-D32*Assumptions!$C$86 | E33: =-E32*Assumptions!$C$86 | F33: =-F32*Assumptions!$C$86 | G33: =-G32*Assumptions!$C$86 | H33: =-H32*Assumptions!$C$86 | I33: =-I32*Assumptions!$C$86 | J33: =-J32*Assumptions!$C$86 | K33: =-K32*Assumptions!$C$86 | ... M33: =-M32*Assumptions!$C$86
B34: SKBA · HoldCo 크레딧비용 배분 | D34: =-Assumptions!$C$104*Assumptions!$C$100 | E34: =-Assumptions!$C$104*Assumptions!$C$100 | F34: =-Assumptions!$C$104*Assumptions!$C$100 | G34: =-Assumptions!$C$104*Assumptions!$C$100 | H34: =-Assumptions!$C$104*Assumptions!$C$100 | I34: =-Assumptions!$C$104*Assumptions!$C$100 | J34: =-Assumptions!$C$104*Assumptions!$C$100 | K34: =-Assumptions!$C$104*Assumptions!$C$100 | ... M34: =-Assumptions!$C$104*Assumptions!$C$100
B35: SKBA FCFE | D35: =D26+D32+D33+D34 | E35: =E26+E32+E33+E34 | F35: =F26+F32+F33+F34 | G35: =G26+G32+G33+G34 | H35: =H26+H32+H33+H34 | I35: =I26+I32+I33+I34 | J35: =J26+J32+J33+J34 | K35: =K26+K32+K33+K34 | ... M35: =M26+M32+M33+M34
B36: SKOT · DOE 이자 (3.5%) | D36: =-Assumptions!$C$106*Assumptions!$C$107 | E36: =-Assumptions!$C$106*Assumptions!$C$107 | F36: =-Assumptions!$C$106*Assumptions!$C$107 | G36: =-Assumptions!$C$106*Assumptions!$C$107 | H36: =-Assumptions!$C$106*Assumptions!$C$107 | I36: =-Assumptions!$C$106*Assumptions!$C$107 | J36: =-Assumptions!$C$106*Assumptions!$C$107 | K36: =-Assumptions!$C$106*Assumptions!$C$107 | ... M36: =-Assumptions!$C$106*Assumptions!$C$107
B37: SKOT · DOE 이자 tax shield | D37: =-D36*Assumptions!$C$86 | E37: =-E36*Assumptions!$C$86 | F37: =-F36*Assumptions!$C$86 | G37: =-G36*Assumptions!$C$86 | H37: =-H36*Assumptions!$C$86 | I37: =-I36*Assumptions!$C$86 | J37: =-J36*Assumptions!$C$86 | K37: =-K36*Assumptions!$C$86 | ... M37: =-M36*Assumptions!$C$86
B38: 메자닌 연상환액 | D38: =Assumptions!$C$108/(Assumptions!$C$111-Assumptions!$C$110+1) | E38: =Assumptions!$C$108/(Assumptions!$C$111-Assumptions!$C$110+1) | F38: =Assumptions!$C$108/(Assumptions!$C$111-Assumptions!$C$110+1) | G38: =Assumptions!$C$108/(Assumptions!$C$111-Assumptions!$C$110+1) | H38: =Assumptions!$C$108/(Assumptions!$C$111-Assumptions!$C$110+1) | I38: =Assumptions!$C$108/(Assumptions!$C$111-Assumptions!$C$110+1) | J38: =Assumptions!$C$108/(Assumptions!$C$111-Assumptions!$C$110+1) | K38: =Assumptions!$C$108/(Assumptions!$C$111-Assumptions!$C$110+1) | ... M38: =Assumptions!$C$108/(Assumptions!$C$111-Assumptions!$C$110+1)
B39: 메자닌 기초잔액 | D39: =MAX(0,Assumptions!$C$108-D38*MAX(0,MIN((2026)-Assumptions!$C$110,Assumptions!$C$111-Assumptions!$C$110+1))) | E39: =MAX(0,Assumptions!$C$108-E38*MAX(0,MIN((2027)-Assumptions!$C$110,Assumptions!$C$111-Assumptions!$C$110+1))) | F39: =MAX(0,Assumptions!$C$108-F38*MAX(0,MIN((2028)-Assumptions!$C$110,Assumptions!$C$111-Assumptions!$C$110+1))) | G39: =MAX(0,Assumptions!$C$108-G38*MAX(0,MIN((2029)-Assumptions!$C$110,Assumptions!$C$111-Assumptions!$C$110+1))) | H39: =MAX(0,Assumptions!$C$108-H38*MAX(0,MIN((2030)-Assumptions!$C$110,Assumptions!$C$111-Assumptions!$C$110+1))) | I39: =MAX(0,Assumptions!$C$108-I38*MAX(0,MIN((2031)-Assumptions!$C$110,Assumptions!$C$111-Assumptions!$C$110+1))) | J39: =MAX(0,Assumptions!$C$108-J38*MAX(0,MIN((2032)-Assumptions!$C$110,Assumptions!$C$111-Assumptions!$C$110+1))) | K39: =MAX(0,Assumptions!$C$108-K38*MAX(0,MIN((2033)-Assumptions!$C$110,Assumptions!$C$111-Assumptions!$C$110+1))) | L39: =MAX(0,Assumptions!$C$108-L38*MAX(0,MIN((2034)-Assumptions!$C$110,Assumptions!$C$111-Assumptions!$C$110+1))) | M39: =MAX(0,Assumptions!$C$108-M38*MAX(0,MIN((2035)-Assumptions!$C$110,Assumptions!$C$111-Assumptions!$C$110+1)))
B40: 메자닌 원금상환 (amort, AMPC재원) | D40: =-IF(AND((2026)>=Assumptions!$C$110,(2026)<=Assumptions!$C$111),MIN(D39,D38),0) | E40: =-IF(AND((2027)>=Assumptions!$C$110,(2027)<=Assumptions!$C$111),MIN(E39,E38),0) | F40: =-IF(AND((2028)>=Assumptions!$C$110,(2028)<=Assumptions!$C$111),MIN(F39,F38),0) | G40: =-IF(AND((2029)>=Assumptions!$C$110,(2029)<=Assumptions!$C$111),MIN(G39,G38),0) | H40: =-IF(AND((2030)>=Assumptions!$C$110,(2030)<=Assumptions!$C$111),MIN(H39,H38),0) | I40: =-IF(AND((2031)>=Assumptions!$C$110,(2031)<=Assumptions!$C$111),MIN(I39,I38),0) | J40: =-IF(AND((2032)>=Assumptions!$C$110,(2032)<=Assumptions!$C$111),MIN(J39,J38),0) | K40: =-IF(AND((2033)>=Assumptions!$C$110,(2033)<=Assumptions!$C$111),MIN(K39,K38),0) | L40: =-IF(AND((2034)>=Assumptions!$C$110,(2034)<=Assumptions!$C$111),MIN(L39,L38),0) | M40: =-IF(AND((2035)>=Assumptions!$C$110,(2035)<=Assumptions!$C$111),MIN(M39,M38),0)
B41: SKOT · 메자닌 배당 (7%, 잔액기준) | D41: =-D39*Assumptions!$C$109 | E41: =-E39*Assumptions!$C$109 | F41: =-F39*Assumptions!$C$109 | G41: =-G39*Assumptions!$C$109 | H41: =-H39*Assumptions!$C$109 | I41: =-I39*Assumptions!$C$109 | J41: =-J39*Assumptions!$C$109 | K41: =-K39*Assumptions!$C$109 | ... M41: =-M39*Assumptions!$C$109
B42: SKOT · HoldCo 크레딧비용 배분 | D42: =-Assumptions!$C$113*Assumptions!$C$100 | E42: =-Assumptions!$C$113*Assumptions!$C$100 | F42: =-Assumptions!$C$113*Assumptions!$C$100 | G42: =-Assumptions!$C$113*Assumptions!$C$100 | H42: =-Assumptions!$C$113*Assumptions!$C$100 | I42: =-Assumptions!$C$113*Assumptions!$C$100 | J42: =-Assumptions!$C$113*Assumptions!$C$100 | K42: =-Assumptions!$C$113*Assumptions!$C$100 | ... M42: =-Assumptions!$C$113*Assumptions!$C$100
B43: SKOT FCFE (보통주 귀속) | D43: =D27+D36+D37+D41+D40+D42 | E43: =E27+E36+E37+E41+E40+E42 | F43: =F27+F36+F37+F41+F40+F42 | G43: =G27+G36+G37+G41+G40+G42 | H43: =H27+H36+H37+H41+H40+H42 | I43: =I27+I36+I37+I41+I40+I42 | J43: =J27+J36+J37+J41+J40+J42 | K43: =K27+K36+K37+K41+K40+K42 | ... M43: =M27+M36+M37+M41+M40+M42
B44: OT CFADS (EBITDA-유지capex) | D44: =SKOT!D19-SKOT!D15+SKOT!D32 | E44: =SKOT!E19-SKOT!E15+SKOT!E32 | F44: =SKOT!F19-SKOT!F15+SKOT!F32 | G44: =SKOT!G19-SKOT!G15+SKOT!G32 | H44: =SKOT!H19-SKOT!H15+SKOT!H32 | I44: =SKOT!I19-SKOT!I15+SKOT!I32 | J44: =SKOT!J19-SKOT!J15+SKOT!J32 | K44: =SKOT!K19-SKOT!K15+SKOT!K32 | ... M44: =SKOT!M19-SKOT!M15+SKOT!M32
...
